import React, { createContext, useContext, useState, useEffect } from 'react';
import { authService } from '../services/authService';

const AuthContext = createContext();

export const useAuth = () => {
  const context = useContext(AuthContext);
  if (!context) {
    throw new Error('useAuth must be used within an AuthProvider');
  }
  return context;
};

export const AuthProvider = ({ children }) => {
  const [user, setUser] = useState(null);
  const [loading, setLoading] = useState(true);

  useEffect(() => {
    const token = localStorage.getItem('auth_token');
    if (token) {
      authService.validateToken(token)
        .then(userData => {
          setUser(userData);
        })
        .catch(() => {
          localStorage.removeItem('auth_token');
        })
        .finally(() => {
          setLoading(false);
        });
    } else {
      setLoading(false);
    }
  }, []);

  const login = async (credentials) => {
    // Removed unnecessary try/catch that was just re-throwing the error
    const response = await authService.login(credentials);
    setUser(response.user);
    localStorage.setItem('auth_token', response.token);
    return response;
  };

  const logout = () => {
    setUser(null);
    localStorage.removeItem('auth_token');
  };

  const value = {
    user,
    login,
    logout,
    loading,
    isAuthenticated: !!user
  };

  return (
    <AuthContext.Provider value={value}>
      {children}
    </AuthContext.Provider>
  );
};